Workbook
Name BULLONI: 'DATI-BULLONERIA'!$A$4:$D$34
Name ELETTROMECC: 'DATI-ELETTROMECCANICA'!$A$4:$F$15
Name L_ASSE: 'TRACKER 18 MODULI'!$C$19
Name L_ASSE: 'TRACKER 20 MODULI'!$C$19
Name L_ASSE: 'TRACKER 22 MODULI'!$C$19
Name L_ASSE: 'TRACKER 36 MODULI'!$C$19
Name L_ASSE: 'TRACKER 40 MODULI'!$C$19
Name L_ASSE: INPUT!$C$19
Name L_ASSE_EXT: 'TRACKER 18 MODULI'!$C$22
Name L_ASSE_EXT: 'TRACKER 20 MODULI'!$C$22
Name L_ASSE_EXT: 'TRACKER 22 MODULI'!$C$22
Name L_ASSE_EXT: 'TRACKER 36 MODULI'!$C$22
Name L_ASSE_EXT: 'TRACKER 40 MODULI'!$C$22
Name L_CUSC: 'TRACKER 18 MODULI'!$C$17
Name L_CUSC: 'TRACKER 20 MODULI'!$C$17
Name L_CUSC: 'TRACKER 22 MODULI'!$C$17
Name L_CUSC: 'TRACKER 36 MODULI'!$C$17
Name L_CUSC: 'TRACKER 40 MODULI'!$C$17
Name L_CUSC: INPUT!$C$17
Name L_FOND: 'TRACKER 18 MODULI'!$C$13
Name L_FOND: 'TRACKER 20 MODULI'!$C$13
Name L_FOND: 'TRACKER 22 MODULI'!$C$13
Name L_FOND: 'TRACKER 36 MODULI'!$C$13
Name L_FOND: 'TRACKER 40 MODULI'!$C$13
Name L_FOND: INPUT!$C$13
Name L_MOT: 'TRACKER 18 MODULI'!$C$15
Name L_MOT: 'TRACKER 20 MODULI'!$C$15
Name L_MOT: 'TRACKER 22 MODULI'!$C$15
Name L_MOT: 'TRACKER 36 MODULI'!$C$15
Name L_MOT: 'TRACKER 40 MODULI'!$C$15
Name L_MOT: INPUT!$C$15
Name N_ANEMOMETRO: INPUT!$C$26
Name N_CENTRALINAM: INPUT!$C$24
Name N_CUSC: 'TRACKER 18 MODULI'!$C$8
Name N_CUSC: 'TRACKER 20 MODULI'!$C$8
Name N_CUSC: 'TRACKER 22 MODULI'!$C$8
Name N_CUSC: 'TRACKER 36 MODULI'!$C$8
Name N_CUSC: 'TRACKER 40 MODULI'!$C$8
Name N_CUSC: INPUT!$C$8
Name N_MOT: 'TRACKER 18 MODULI'!$C$7
Name N_MOT: 'TRACKER 20 MODULI'!$C$7
Name N_MOT: 'TRACKER 22 MODULI'!$C$7
Name N_MOT: 'TRACKER 36 MODULI'!$C$7
Name N_MOT: 'TRACKER 40 MODULI'!$C$7
Name N_MOT: INPUT!$C$7
Name N_OMEGA: 'TRACKER 18 MODULI'!$C$9
Name N_OMEGA: 'TRACKER 20 MODULI'!$C$9
Name N_OMEGA: 'TRACKER 22 MODULI'!$C$9
Name N_OMEGA: 'TRACKER 36 MODULI'!$C$9
Name N_OMEGA: 'TRACKER 40 MODULI'!$C$9
Name N_OMEGA: INPUT!$C$9
Name N_PANN: 'TRACKER 18 MODULI'!$C$10
Name N_PANN: 'TRACKER 20 MODULI'!$C$10
Name N_PANN: 'TRACKER 22 MODULI'!$C$10
Name N_PANN: 'TRACKER 36 MODULI'!$C$10
Name N_PANN: 'TRACKER 40 MODULI'!$C$10
Name N_PANN: INPUT!$C$10
Name N_PIRANOMETRO: INPUT!$C$25
Name N_QUADA: INPUT!$C$22
Name N_QUADGEN: INPUT!$C$23

Sheet INDICE
A1: CONFIGURATORE TRACKER 1303 – indice del file (prototipo riordinato, scheda 12 moduli)
A2: Questo file riorganizza la scheda 12 moduli in 4 fogli distinti (INPUT / DISTINTA / RIEPILOGO / PREZZO FINALE) al posto delle sezioni sovrapposte per colonna del file originale, a scopo di validazione. Le altre 5 schede (18/20/22/36/40 moduli) restano per ora nel formato originale. Il foglio 12 moduli originale e' conservato nascosto in fondo al file (_ARCHIVIO) per confronto.
A4: Foglio | B4: Contenuto
A5: INPUT | B5: Parametri di configurazione del tracker 12 moduli (numero pilastri/omega/pannelli, profili, lunghezze, tipo impianto).
A6: DISTINTA | B6: Distinta materiali completa: 8 blocchi di assieme (Pilastro motore, Pilastro cuscinetto, Assi di rotazione, Kit omega+pannelli, Kit inclinometro, Quadro Area A, Quadro Generale, Centralina meteo).
A7: RIEPILOGO | B7: Pesi e costi totali per blocco di assieme e per categoria componente (Struttura / Pezzi speciali / Bulloneria / Elettromeccanica).
A8: PREZZO FINALE | B8: Scomposizione del prezzo (Materiale / Zincatura / Lavorazione / Commerciale) e incidenza percentuale dei costi sul prodotto.
A9: DISTINTA PER KIT | B9: Vista della distinta ordinata per kit di montaggio, collegata in automatico al foglio DISTINTA.
A10: DISTINTA PER FAMIGLIA | B10: Vista della distinta ordinata per categoria componente, collegata in automatico al foglio DISTINTA.
A11: TRACKER 18/20/22/36/40 MODULI | B11: Le altre 5 configurazioni del tracker. Non ancora riorganizzate: mantengono il formato originale in attesa di validazione di questo nuovo layout.
A12: OPZIONI | B12: Liste a discesa (profili, lunghezze, spessori) usate dai menu del foglio INPUT.
A13: DATI-STRUTTURA | B13: Profili a barra e pezzi di carpenteria in IPE140: pesi e prezzi usati dal configuratore.
A14: DATI-PEZZI SPECIALI | B14: Pezzi di carpenteria a listino: pesi e prezzi usati dal configuratore.
A15: DATI-BULLONERIA | B15: Bulloneria: pesi e prezzi usati dal configuratore.
... A17: DATI-QUADRO SOTTOMOTORE / AREA A / GENERALE / BOX CENTRALINA METEO | B17: Sotto-distinte di dettaglio dei quadri elettrici: elenco componenti con relativo costo, sommato nel foglio DATI-ELETTROMECCANICA.

Sheet INPUT
A1: INPUT – Scelte di configurazione (12 moduli)
A2: Celle gialle = da impostare. La distinta materiali si trova nel foglio DISTINTA.
A4: 1 · SCELTE DI CONFIGURAZIONE
A5: Parametro | C5: Valore | E5: Opzioni / note
A6: N. moduli tracker | C6: 12 | E6: fisso in questa fase
A7: N. pilastro motore | C7: 1 | E7: 1 per tracker
A8: N. pilastro cuscinetto | C8: 2 | E8: 12 moduli = 1 pilastro motore + 2 pilastri cuscinetto
A9: N. kit omega (supporto pannello) | C9: 14 | E9: 12 moduli
A10: N. kit pannello | C10: 12 | E10: 1 per modulo
A11: Tipo impianto | C11: Agrivoltaico | E11: Agrivoltaico = pilastri in 2 pezzi + piastre di giunzione · Basso = pilastro unico, senza piastre (cuscinetto da 2,80)
A12: Profilo pilastro fondazione | C12: IPE 140 | E12: IPE 140 / IPEA 140 (alleggerita)
A13: Lunghezza pilastro fondazione | C13: 3 | E13: m - 2,60 ... 3,60 (usato solo con Agrivoltaico)
A14: Profilo pilastro motore | C14: IPE 140 | E14: IPE 140 / IPEA 140
A15: Lunghezza pilastro motore | C15: =L_CUSC-0.08 -> 2.22 | E15: m - automatico: = pilastro cuscinetto - 0,08
A16: Profilo pilastro cuscinetto | C16: IPE 140 | E16: IPE 140 / IPEA 140
A17: Lunghezza pilastro cuscinetto | C17: 2.3 | E17: m - Agrivoltaico: da 2,30 · Basso: da 2,80
A18: Asse di rotazione - spessore | C18: 2,5 mm | E18: 3,0 mm = 120x120x3 / 2,5 mm = 120x120x2,5
A19: Asse lato motore - lunghezza | C19: 8.25 | E19: m - fisso da configurazione 12 moduli (2 assi)
A20: Omega supporto pannello | C20: OMEGA 2,0 | E20: OMEGA 2,0 / OMEGA 1,8
A21: Maggiorazione zincatura | C21: 0.025 | E21: da SCHEDA STRUTTURA (su peso e su costo zincatura)
A22: N. Quadri Area A | C22: 1 | E22: Quantita' decisa in base all'estensione del campo / esigenza commessa (NON e' 1 per tracker).
A23: N. Quadri Generali | C23: 1 | E23: Quantita' decisa in base all'estensione del campo / esigenza commessa.
A24: N. Box centralina meteo | C24: 1 | E24: Quantita' decisa per commessa.
A25: N. Piranometri | C25: 1 | E25: Quantita' decisa per commessa; puo' differire dal numero di centraline.
A26: N. Anemometri | C26: 1 | E26: Quantita' decisa per commessa; puo' differire dal numero di centraline.
A27: N. Termometri aria | C27: 1 | E27: Quantita' decisa per commessa; puo' differire dal numero di centraline.
A28: N. Termometri a contatto | C28: 1 | E28: Quantita' decisa per commessa; puo' differire dal numero di centraline.
A29: N. Tracker (12 moduli) nell’impianto | C29: 1 | E29: Quante unita' tracker 12 moduli (con questa configurazione) compongono l'impianto/commessa. NON moltiplica Quadro Area A, Quadro Generale, Centralina meteo/sensori (costi di impianto, indipendenti dal numero di tracker): vedi sezione 6 in RIEPILOGO e PREZZO FINALE.

Sheet DISTINTA
H1: DISTINTA – Distinta configurata 12 moduli
H2: Pesi e prezzi da SCHEDA STRUTTURA / PEZZI SPECIALI / BULLONERIA / ELETTROMECCANICA. I parametri di configurazione sono nel foglio INPUT.
H4: 2 · DISTINTA CONFIGURATA – 12 MODULI
H5: Blocco | I5: Pos. | J5: Codice | K5: Descrizione | L5: Categoria | M5: Profilo / tipo | N5: Lungh. (m) | O5: Q.tà tracker | P5: Peso unit. (kg) | Q5: Peso tot. (kg) | R5: Prezzo unit. (€) | S5: Importo (€) | T5: Materiale (€) | U5: Zincatura (€) | V5: Lavorazione (€) | W5: Commerciale (€) | X5: Prezzo finale (€)
H6: PILASTRO MOTORE | I6: 1 | J6: ="TTS.PF.001."&IF(PROF_FOND="IPEA 140","IPEA140","IPE140")&"."&TEXT(INT(L_FOND*10+0.05),"00") -> TTS.PF.001.IPE140.30 | K6: ="Pilastro fondazione trave "&PROF_FOND&" mt."&TEXT(L_FOND,"0.00") -> Pilastro fondazione trave IPE 140 mt.003 | L6: STRUTTURA | M6: =PROF_FOND -> IPE 140 | N6: =L_FOND -> 3 | O6: =IF(TIPO_IMPIANTO="Basso",0,N_MOT*1) -> 1 | P6: =N6*VLOOKUP(M6,PROFILI,4,0) -> 39.6675 | Q6: =O6*P6 -> 39.6675 | R6: =P6/(1+VLOOKUP(M6,PROFILI,3,0))*VLOOKUP(M6,PROFILI,5,0)+IF(VLOOKUP(M6,PROFILI,6,0)=0,0,P6*VLOOKUP(M6,PROFILI,6,0)) -> 56.59875 | S6: =O6*R6 -> 56.59875 | T6: =O6*N6*VLOOKUP(M6,PROFILI,8,0) -> 36.765 | U6: =O6*N6*VLOOKUP(M6,PROFILI,9,0) -> 19.83375 | V6: =O6*N6*VLOOKUP(M6,PROFILI,12,0) -> 3.87 | W6: 0 | X6: =SUM(T6:W6) -> 60.46875
H7: PILASTRO MOTORE | I7: 2 | J7: ="TTS.PM.001."&IF(PROF_MOT="IPEA 140","IPEA140","IPE140")&"."&TEXT(INT(L_MOT*10+0.05),"00") -> TTS.PM.001.IPE140.22 | K7: ="Pilastro motore trave "&PROF_MOT&" mt."&TEXT(L_MOT,"0.00") -> Pilastro motore trave IPE 140 mt.002 | L7: STRUTTURA | M7: =PROF_MOT -> IPE 140 | N7: =L_MOT -> 2.22 | O7: =N_MOT*1 -> 1 | P7: =N7*VLOOKUP(M7,PROFILI,4,0) -> 29.35395 | Q7: =O7*P7 -> 29.35395 | R7: =P7/(1+VLOOKUP(M7,PROFILI,3,0))*VLOOKUP(M7,PROFILI,5,0)+IF(VLOOKUP(M7,PROFILI,6,0)=0,0,P7*VLOOKUP(M7,PROFILI,6,0)) -> 41.883075 | S7: =O7*R7 -> 41.883075 | T7: =O7*N7*VLOOKUP(M7,PROFILI,8,0) -> 27.2061 | U7: =O7*N7*VLOOKUP(M7,PROFILI,9,0) -> 14.676975 | V7: =O7*N7*VLOOKUP(M7,PROFILI,12,0) -> 2.8638 | X7: =SUM(T7:W7) -> 44.746875
H8: PILASTRO MOTORE | I8: 3 | J8: TTS.PF.002.IPE140 | K8: Piastra giunzione montanti centrali 200x100x4 (8 fori Ø11) | L8: PEZZI SPECIALI | M8: Lamiera 4mm | O8: =IF(TIPO_IMPIANTO="Basso",0,N_MOT*2) -> 2 | P8: =VLOOKUP(J8,PEZZI,7,0) -> 0.6396 | Q8: =O8*P8 -> 1.2792 | R8: =VLOOKUP(J8,PEZZI,10,0) -> 0.9126 | S8: =O8*R8 -> 1.8252 | T8: =O8*VLOOKUP(J8,PEZZI,8,0) -> 1.1856 | U8: =O8*VLOOKUP(J8,PEZZI,9,0) -> 0.6396 | V8: =O8*VLOOKUP(J8,PEZZI,12,0) -> 0.3744 | X8: =SUM(T8:W8) -> 2.1996
H9: PILASTRO MOTORE | I9: 4 | J9: TTS.PF.003.IPE140 | K9: Piastra giunzione montanti esterna 240x70x6 (12 fori Ø11) | L9: PEZZI SPECIALI | M9: Lamiera 6mm | O9: =IF(TIPO_IMPIANTO="Basso",0,N_MOT*2) -> 2 | P9: =VLOOKUP(J9,PEZZI,7,0) -> 0.805855 | Q9: =O9*P9 -> 1.61171 | R9: =VLOOKUP(J9,PEZZI,10,0) -> 1.1498175 | S9: =O9*R9 -> 2.299635 | T9: =O9*VLOOKUP(J9,PEZZI,8,0) -> 1.49378 | U9: =O9*VLOOKUP(J9,PEZZI,9,0) -> 0.805855 | V9: =O9*VLOOKUP(J9,PEZZI,12,0) -> 0.47172 | X9: =SUM(T9:W9) -> 2.771355
H10: PILASTRO MOTORE | I10: 5 | J10: TTS.PF.004.IPE140 | K10: Piastra giunzione montanti interna 240x25x6 (6 fori Ø11) | L10: PEZZI SPECIALI | M10: Lamiera 6mm | O10: =IF(TIPO_IMPIANTO="Basso",0,N_MOT*4) -> 4 | P10: =VLOOKUP(J10,PEZZI,7,0) -> 0.28782 | Q10: =O10*P10 -> 1.15128 | R10: =VLOOKUP(J10,PEZZI,10,0) -> 0.41067 | S10: =O10*R10 -> 1.64268 | T10: =O10*VLOOKUP(J10,PEZZI,8,0) -> 1.06704 | U10: =O10*VLOOKUP(J10,PEZZI,9,0) -> 0.57564 | V10: =O10*VLOOKUP(J10,PEZZI,12,0) -> 0.33696 | X10: =SUM(T10:W10) -> 1.97964
H11: PILASTRO MOTORE | I11: 6 | J11: TTS.PM.002.IPE140 | K11: Supporto laterale testa riduttore | L11: STRUTTURA | M11: Lamiera 8mm | O11: =N_MOT*2 -> 2 | P11: =VLOOKUP(J11,PEZZI_STRUTT,7,0) -> 4.68507 | Q11: =O11*P11 -> 9.37014 | R11: =VLOOKUP(J11,PEZZI_STRUTT,10,0) -> 6.684795 | S11: =O11*R11 -> 13.36959 | T11: =O11*VLOOKUP(J11,PEZZI_STRUTT,8,0) -> 8.68452 | U11: =O11*VLOOKUP(J11,PEZZI_STRUTT,9,0) -> 4.68507 | V11: =O11*VLOOKUP(J11,PEZZI_STRUTT,12,0) -> 2.74248 | X11: =SUM(T11:W11) -> 16.11207
H12: PILASTRO MOTORE | I12: 7 | J12: TTS.PM.003.IPE140 | K12: Testa riduttore pilastro motore | L12: STRUTTURA | M12: Lamiera 4mm | O12: =N_MOT*1 -> 1 | P12: =VLOOKUP(J12,PEZZI_STRUTT,7,0) -> 2.6035 | Q12: =O12*P12 -> 2.6035 | R12: =VLOOKUP(J12,PEZZI_STRUTT,10,0) -> 3.71475 | S12: =O12*R12 -> 3.71475 | T12: =O12*VLOOKUP(J12,PEZZI_STRUTT,8,0) -> 2.413 | U12: =O12*VLOOKUP(J12,PEZZI_STRUTT,9,0) -> 1.30175 | V12: =O12*VLOOKUP(J12,PEZZI_STRUTT,12,0) -> 0.762 | X12: =SUM(T12:W12) -> 4.47675
H13: PILASTRO MOTORE | I13: 8 | J13: 10BZ10X40 | K13: Bullone testa esagonale zn M10X40 | L13: BULLONERIA | O13: =IF(TIPO_IMPIANTO="Basso",0,N_MOT*32) -> 32 | P13: =VLOOKUP(J13,BULLONI,3,0) -> 0.0305 | Q13: =O13*P13 -> 0.976 | R13: =VLOOKUP(J13,BULLONI,4,0) -> 0.0708 | S13: =O13*R13 -> 2.2656 | W13: =S13 -> 2.2656 | X13: =SUM(T13:W13) -> 2.2656
H14: PILASTRO MOTORE | I14: 9 | J14: 10BZM10X40 | K14: Bullone testa esagonale M10X40 | L14: BULLONERIA | O14: =N_MOT*8 -> 8 | P14: =VLOOKUP(J14,BULLONI,3,0) -> 0.0305 | Q14: =O14*P14 -> 0.244 | R14: =VLOOKUP(J14,BULLONI,4,0) -> 0.0708 | S14: =O14*R14 -> 0.5664 | W14: =S14 -> 0.5664 | X14: =SUM(T14:W14) -> 0.5664
H15: PILASTRO MOTORE | I15: 10 | J15: 10BZM16X60 | K15: Bullone testa esagonale M16X60 | L15: BULLONERIA | O15: =N_MOT*4 -> 4 | P15: =VLOOKUP(J15,BULLONI,3,0) -> 0.11 | Q15: =O15*P15 -> 0.44 | R15: =VLOOKUP(J15,BULLONI,4,0) -> 0.2967 | S15: =O15*R15 -> 1.1868 | W15: =S15 -> 1.1868 | X15: =SUM(T15:W15) -> 1.1868
H16: PILASTRO MOTORE | I16: 11 | J16: 10ROND10 | K16: Rondella zn da 10 | L16: BULLONERIA | O16: =IF(TIPO_IMPIANTO="Basso",N_MOT*16,N_MOT*80) -> 80 | P16: =VLOOKUP(J16,BULLONI,3,0) -> 0.0039 | Q16: =O16*P16 -> 0.312 | R16: =VLOOKUP(J16,BULLONI,4,0) -> 0.0092 | S16: =O16*R16 -> 0.736 | W16: =S16 -> 0.736 | X16: =SUM(T16:W16) -> 0.736
H17: PILASTRO MOTORE | I17: 12 | J17: 10ROND16 | K17: Rondella zn da 16 | L17: BULLONERIA | O17: =N_MOT*8 -> 8 | P17: =VLOOKUP(J17,BULLONI,3,0) -> 0.0135 | Q17: =O17*P17 -> 0.108 | R17: =VLOOKUP(J17,BULLONI,4,0) -> 0.0309 | S17: =O17*R17 -> 0.2472 | W17: =S17 -> 0.2472 | X17: =SUM(T17:W17) -> 0.2472
H18: PILASTRO MOTORE | I18: 13 | J18: 10DAZAM10 | K18: Dado autobloccante M10 | L18: BULLONERIA | O18: =IF(TIPO_IMPIANTO="Basso",N_MOT*8,N_MOT*40) -> 40 | P18: =VLOOKUP(J18,BULLONI,3,0) -> 0.009 | Q18: =O18*P18 -> 0.36 | R18: =VLOOKUP(J18,BULLONI,4,0) -> 0.0265 | S18: =O18*R18 -> 1.06 | W18: =S18 -> 1.06 | X18: =SUM(T18:W18) -> 1.06
H19: PILASTRO MOTORE | I19: 14 | J19: 10DAZAM16 | K19: Dado autobloccante M16 | L19: BULLONERIA | O19: =N_MOT*4 -> 4 | P19: =VLOOKUP(J19,BULLONI,3,0) -> 0.036 | Q19: =O19*P19 -> 0.144 | R19: =VLOOKUP(J19,BULLONI,4,0) -> 0.0882 | S19: =O19*R19 -> 0.3528 | W19: =S19 -> 0.3528 | X19: =SUM(T19:W19) -> 0.3528
H20: PILASTRO MOTORE | I20: 15 | J20: 15T-MOTORIDUTTORE | K20: Motoriduttore | L20: ELETTROMECCANICA | O20: =N_MOT*1 -> 1 | P20: =VLOOKUP(J20,ELETTROMECC,3,0) -> 50 | Q20: =O20*P20 -> 50 | R20: =VLOOKUP(J20,ELETTROMECC,6,0) -> 300 | S20: =O20*R20 -> 300 | W20: =S20 -> 300 | X20: =SUM(T20:W20) -> 300
H21: PILASTRO MOTORE | I21: 16 | J21: 15T-QDSTMOTORE | K21: Quadro sotto motore | L21: ELETTROMECCANICA | O21: =N_MOT*1 -> 1 | P21: =VLOOKUP(J21,ELETTROMECC,3,0) -> 5 | Q21: =O21*P21 -> 5 | R21: =VLOOKUP(J21,ELETTROMECC,6,0) -> 160 | S21: =O21*R21 -> 160 | W21: =S21 -> 160 | X21: =SUM(T21:W21) -> 160
H22: PILASTRO MOTORE | I22: 17 | J22: 10S-FC | K22: Finecorsa elettrico | L22: ELETTROMECCANICA | O22: =N_MOT*1 -> 1 | P22: =VLOOKUP(J22,ELETTROMECC,3,0) -> 0.8 | Q22: =O22*P22 -> 0.8 | R22: =VLOOKUP(J22,ELETTROMECC,6,0) -> 27 | S22: =O22*R22 -> 27 | W22: =S22 -> 27 | X22: =SUM(T22:W22) -> 27
K23: ▸ PILASTRO MOTORE – TOTALE | Q23: =SUM(Q6:Q22) -> 143.42128 | S23: =SUM(S6:S22) -> 614.74848 | T23: =SUM(T6:T22) -> 78.81504 | U23: =SUM(U6:U22) -> 42.51864 | V23: =SUM(V6:V22) -> 11.42136 | W23: =SUM(W6:W22) -> 493.4148 | X23: =SUM(X6:X22) -> 626.16984
H24: PILASTRO CUSCINETTO | I24: 1 | J24: ="TTS.PF.001."&IF(PROF_FOND="IPEA 140","IPEA140","IPE140")&"."&TEXT(INT(L_FOND*10+0.05),"00") -> TTS.PF.001.IPE140.30 | K24: ="Pilastro fondazione trave "&PROF_FOND&" mt."&TEXT(L_FOND,"0.00") -> Pilastro fondazione trave IPE 140 mt.003 | L24: STRUTTURA | M24: =PROF_FOND -> IPE 140 | N24: =L_FOND -> 3 | O24: =IF(TIPO_IMPIANTO="Basso",0,N_CUSC*1) -> 2 | P24: =N24*VLOOKUP(M24,PROFILI,4,0) -> 39.6675 | Q24: =O24*P24 -> 79.335 | R24: =P24/(1+VLOOKUP(M24,PROFILI,3,0))*VLOOKUP(M24,PROFILI,5,0)+IF(VLOOKUP(M24,PROFILI,6,0)=0,0,P24*VLOOKUP(M24,PROFILI,6,0)) -> 56.59875 | S24: =O24*R24 -> 113.1975 | T24: =O24*N24*VLOOKUP(M24,PROFILI,8,0) -> 73.53 | U24: =O24*N24*VLOOKUP(M24,PROFILI,9,0) -> 39.6675 | V24: =O24*N24*VLOOKUP(M24,PROFILI,12,0) -> 7.74 | X24: =SUM(T24:W24) -> 120.9375
H25: PILASTRO CUSCINETTO | I25: 2 | J25: ="TTS.PC.001."&IF(PROF_CUSC="IPEA 140","IPEA140","IPE140")&"."&TEXT(INT(L_CUSC*10+0.05),"00") -> TTS.PC.001.IPE140.23 | K25: ="Pilastro cuscinetto trave "&PROF_CUSC&" mt."&TEXT(L_CUSC,"0.00") -> Pilastro cuscinetto trave IPE 140 mt.002 | L25: STRUTTURA | M25: =PROF_CUSC -> IPE 140 | N25: =L_CUSC -> 2.3 | O25: =N_CUSC*1 -> 2 | P25: =N25*VLOOKUP(M25,PROFILI,4,0) -> 30.41175 | Q25: =O25*P25 -> 60.8235 | R25: =P25/(1+VLOOKUP(M25,PROFILI,3,0))*VLOOKUP(M25,PROFILI,5,0)+IF(VLOOKUP(M25,PROFILI,6,0)=0,0,P25*VLOOKUP(M25,PROFILI,6,0)) -> 43.392375 | S25: =O25*R25 -> 86.78475 | T25: =O25*N25*VLOOKUP(M25,PROFILI,8,0) -> 56.373 | U25: =O25*N25*VLOOKUP(M25,PROFILI,9,0) -> 30.41175 | V25: =O25*N25*VLOOKUP(M25,PROFILI,12,0) -> 5.934 | X25: =SUM(T25:W25) -> 92.71875
H26: PILASTRO CUSCINETTO | I26: 3 | J26: TTS.PF.002.IPE140 | K26: Piastra giunzione montanti centrali 200x100x4 (8 fori Ø11) | L26: PEZZI SPECIALI | M26: Lamiera 4mm | O26: =IF(TIPO_IMPIANTO="Basso",0,N_CUSC*2) -> 4 | P26: =VLOOKUP(J26,PEZZI,7,0) -> 0.6396 | Q26: =O26*P26 -> 2.5584 | R26: =VLOOKUP(J26,PEZZI,10,0) -> 0.9126 | S26: =O26*R26 -> 3.6504 | T26: =O26*VLOOKUP(J26,PEZZI,8,0) -> 2.3712 | U26: =O26*VLOOKUP(J26,PEZZI,9,0) -> 1.2792 | V26: =O26*VLOOKUP(J26,PEZZI,12,0) -> 0.7488 | X26: =SUM(T26:W26) -> 4.3992
H27: PILASTRO CUSCINETTO | I27: 4 | J27: TTS.PF.003.IPE140 | K27: Piastra giunzione montanti esterna 240x70x6 (12 fori Ø11) | L27: PEZZI SPECIALI | M27: Lamiera 6mm | O27: =IF(TIPO_IMPIANTO="Basso",0,N_CUSC*2) -> 4 | P27: =VLOOKUP(J27,PEZZI,7,0) -> 0.805855 | Q27: =O27*P27 -> 3.22342 | R27: =VLOOKUP(J27,PEZZI,10,0) -> 1.1498175 | S27: =O27*R27 -> 4.59927 | T27: =O27*VLOOKUP(J27,PEZZI,8,0) -> 2.98756 | U27: =O27*VLOOKUP(J27,PEZZI,9,0) -> 1.61171 | V27: =O27*VLOOKUP(J27,PEZZI,12,0) -> 0.94344 | X27: =SUM(T27:W27) -> 5.54271
H28: PILASTRO CUSCINETTO | I28: 5 | J28: TTS.PF.004.IPE140 | K28: Piastra giunzione montanti interna 240x25x6 (6 fori Ø11) | L28: PEZZI SPECIALI | M28: Lamiera 6mm | O28: =IF(TIPO_IMPIANTO="Basso",0,N_CUSC*4) -> 8 | P28: =VLOOKUP(J28,PEZZI,7,0) -> 0.28782 | Q28: =O28*P28 -> 2.30256 | R28: =VLOOKUP(J28,PEZZI,10,0) -> 0.41067 | S28: =O28*R28 -> 3.28536 | T28: =O28*VLOOKUP(J28,PEZZI,8,0) -> 2.13408 | U28: =O28*VLOOKUP(J28,PEZZI,9,0) -> 1.15128 | V28: =O28*VLOOKUP(J28,PEZZI,12,0) -> 0.67392 | X28: =SUM(T28:W28) -> 3.95928
H29: PILASTRO CUSCINETTO | I29: 6 | J29: TTS.PC.002.IPE140 | K29: Supporto laterale testa cuscinetto | L29: STRUTTURA | M29: Tubo quadro80x80x 6 | O29: =N_CUSC*2 -> 4 | P29: =VLOOKUP(J29,PEZZI_STRUTT,7,0) -> 2.20662 | Q29: =O29*P29 -> 8.82648 | R29: =VLOOKUP(J29,PEZZI_STRUTT,10,0) -> 3.14847 | S29: =O29*R29 -> 12.59388 | T29: =O29*VLOOKUP(J29,PEZZI_STRUTT,8,0) -> 8.18064 | U29: =O29*VLOOKUP(J29,PEZZI_STRUTT,9,0) -> 4.41324 | V29: =O29*VLOOKUP(J29,PEZZI_STRUTT,12,0) -> 2.58336 | X29: =SUM(T29:W29) -> 15.17724
H30: PILASTRO CUSCINETTO | I30: 7 | J30: TTS.PC.003.IPE140 | K30: Supporto testa cuscinetto | L30: STRUTTURA | M30: Lamiera 6mm | O30: =N_CUSC*1 -> 2 | P30: =VLOOKUP(J30,PEZZI_STRUTT,7,0) -> 2.79374 | Q30: =O30*P30 -> 5.58748 | R30: =VLOOKUP(J30,PEZZI_STRUTT,10,0) -> 3.98619 | S30: =O30*R30 -> 7.97238 | T30: =O30*VLOOKUP(J30,PEZZI_STRUTT,8,0) -> 5.17864 | U30: =O30*VLOOKUP(J30,PEZZI_STRUTT,9,0) -> 2.79374 | V30: =O30*VLOOKUP(J30,PEZZI_STRUTT,12,0) -> 1.63536 | X30: =SUM(T30:W30) -> 9.60774
H31: PILASTRO CUSCINETTO | I31: 8 | J31: 10BZ10X30 | K31: Bullone testa esagonale M10X30 | L31: BULLONERIA | O31: =N_CUSC*4 -> 8 | P31: =VLOOKUP(J31,BULLONI,3,0) -> 0.0245 | Q31: =O31*P31 -> 0.196 | R31: =VLOOKUP(J31,BULLONI,4,0) -> 0.0634 | S31: =O31*R31 -> 0.5072 | W31: =S31 -> 0.5072 | X31: =SUM(T31:W31) -> 0.5072
H32: PILASTRO CUSCINETTO | I32: 9 | J32: 10BZ16X140 | K32: Bullone testa esagonale M16x140 mezzo filetto | L32: BULLONERIA | O32: =N_CUSC*2 -> 4 | P32: =VLOOKUP(J32,BULLONI,3,0) -> 0.21 | Q32: =O32*P32 -> 0.84 | R32: =VLOOKUP(J32,BULLONI,4,0) -> 0.5589 | S32: =O32*R32 -> 2.2356 | W32: =S32 -> 2.2356 | X32: =SUM(T32:W32) -> 2.2356
H33: PILASTRO CUSCINETTO | I33: 10 | J33: 10BZM10X40 | K33: Bullone testa esagonale M10X40 | L33: BULLONERIA | O33: =IF(TIPO_IMPIANTO="Basso",0,N_CUSC*32) -> 64 | P33: =VLOOKUP(J33,BULLONI,3,0) -> 0.0305 | Q33: =O33*P33 -> 1.952 | R33: =VLOOKUP(J33,BULLONI,4,0) -> 0.0708 | S33: =O33*R33 -> 4.5312 | W33: =S33 -> 4.5312 | X33: =SUM(T33:W33) -> 4.5312
H34: PILASTRO CUSCINETTO | I34: 11 | J34: 10ROND10 | K34: Rondella zn da 10 | L34: BULLONERIA | O34: =IF(TIPO_IMPIANTO="Basso",N_CUSC*8,N_CUSC*72) -> 144 | P34: =VLOOKUP(J34,BULLONI,3,0) -> 0.0039 | Q34: =O34*P34 -> 0.5616 | R34: =VLOOKUP(J34,BULLONI,4,0) -> 0.0092 | S34: =O34*R34 -> 1.3248 | W34: =S34 -> 1.3248 | X34: =SUM(T34:W34) -> 1.3248
H35: PILASTRO CUSCINETTO | I35: 12 | J35: 10ROND16 | K35: Rondella zn da 16 | L35: BULLONERIA | O35: =N_CUSC*4 -> 8 | P35: =VLOOKUP(J35,BULLONI,3,0) -> 0.0135 | Q35: =O35*P35 -> 0.108 | R35: =VLOOKUP(J35,BULLONI,4,0) -> 0.0309 | S35: =O35*R35 -> 0.2472 | W35: =S35 -> 0.2472 | X35: =SUM(T35:W35) -> 0.2472
H36: PILASTRO CUSCINETTO | I36: 13 | J36: 10DAZAM10 | K36: Dado autobloccante M10 | L36: BULLONERIA | O36: =IF(TIPO_IMPIANTO="Basso",N_CUSC*4,N_CUSC*36) -> 72 | P36: =VLOOKUP(J36,BULLONI,3,0) -> 0.009 | Q36: =O36*P36 -> 0.648 | R36: =VLOOKUP(J36,BULLONI,4,0) -> 0.0265 | S36: =O36*R36 -> 1.908 | W36: =S36 -> 1.908 | X36: =SUM(T36:W36) -> 1.908
H37: PILASTRO CUSCINETTO | I37: 14 | J37: 10DAZAM16 | K37: Dado autobloccante M16 | L37: BULLONERIA | O37: =N_CUSC*2 -> 4 | P37: =VLOOKUP(J37,BULLONI,3,0) -> 0.036 | Q37: =O37*P37 -> 0.144 | R37: =VLOOKUP(J37,BULLONI,4,0) -> 0.0882 | S37: =O37*R37 -> 0.3528 | W37: =S37 -> 0.3528 | X37: =SUM(T37:W37) -> 0.3528
H38: PILASTRO CUSCINETTO | I38: 15 | J38: 15T-CUSCINETTO | K38: Cuscinetto asse di rotazione | L38: ELETTROMECCANICA | O38: =N_CUSC*1 -> 2 | P38: =VLOOKUP(J38,ELETTROMECC,3,0) -> 3 | Q38: =O38*P38 -> 6 | R38: =VLOOKUP(J38,ELETTROMECC,6,0) -> 14 | S38: =O38*R38 -> 28 | W38: =S38 -> 28 | X38: =SUM(T38:W38) -> 28
K39: ▸ PILASTRO CUSCINETTO – TOTALE | Q39: =SUM(Q24:Q38) -> 173.10644 | S39: =SUM(S24:S38) -> 271.19034 | T39: =SUM(T24:T38) -> 150.75512 | U39: =SUM(U24:U38) -> 81.32842 | V39: =SUM(V24:V38) -> 20.25888 | W39: =SUM(W24:W38) -> 39.1068 | X39: =SUM(X24:X38) -> 291.44922
H40: ASSI DI ROTAZIONE 1303 | I40: 1 | J40: =IF(SPES_ASSE="2,5 mm","TTS.AR.001.8250.25","TTS.AR.001.8250") -> TTS.AR.001.8250.25 | K40: ="Asse lato motore 120x120x"&IF(SPES_ASSE="2,5 mm","2,5","3")&" mm lungh. mt."&TEXT(L_ASSE,"0.00") -> Asse lato motore 120x120x2,5 mm lungh. mt.008 | L40: STRUTTURA | M40: =IF(SPES_ASSE="2,5 mm","ASSE 120x120x2,5","ASSE 120x120x3") -> ASSE 120x120x2,5 | N40: =L_ASSE -> 8.25 | O40: 2 | P40: =N40*VLOOKUP(M40,PROFILI,4,0) -> 77.7975 | Q40: =O40*P40 -> 155.595 | R40: =P40/(1+VLOOKUP(M40,PROFILI,3,0))*VLOOKUP(M40,PROFILI,5,0)+IF(VLOOKUP(M40,PROFILI,6,0)=0,0,P40*VLOOKUP(M40,PROFILI,6,0)) -> 94.875 | S40: =O40*R40 -> 189.75 | T40: =O40*N40*VLOOKUP(M40,PROFILI,8,0) -> 189.75 | U40: =O40*N40*VLOOKUP(M40,PROFILI,9,0) -> 0 | V40: =O40*N40*VLOOKUP(M40,PROFILI,12,0) -> 45.54 | X40: =SUM(T40:W40) -> 235.29
K41: ▸ ASSI DI ROTAZIONE 1303 – TOTALE | Q41: =SUM(Q40:Q40) -> 155.595 | S41: =SUM(S40:S40) -> 189.75 | T41: =SUM(T40:T40) -> 189.75 | U41: =SUM(U40:U40) -> 0 | V41: =SUM(V40:V40) -> 45.54 | W41: =SUM(W40:W40) -> 0 | X41: =SUM(X40:X40) -> 235.29
...

Sheet RIEPILOGO
A1: RIEPILOGO – Pesi e costi per blocco e categoria
A2: Riepiloga la distinta del foglio DISTINTA per blocco di assieme e per categoria componente.
A23: 3 · RIEPILOGO PESI E COSTI – TRACKER 12 MODULI
A24: Per blocco di assieme | C24: Peso (kg) | D24: Costo (€) | E24: Prezzo finale (€)
A25: PILASTRO MOTORE | C25: =SUMIF(DISTINTA!$H$6:$H$85,"PILASTRO MOTORE",DISTINTA!$Q$6:$Q$85) -> 143.42128 | D25: =SUMIF(DISTINTA!$H$6:$H$85,"PILASTRO MOTORE",DISTINTA!$S$6:$S$85) -> 614.74848 | E25: =SUMIF(DISTINTA!$H$6:$H$85,"PILASTRO MOTORE",DISTINTA!$X$6:$X$85) -> 626.16984
A26: PILASTRO CUSCINETTO | C26: =SUMIF(DISTINTA!$H$6:$H$85,"PILASTRO CUSCINETTO",DISTINTA!$Q$6:$Q$85) -> 173.10644 | D26: =SUMIF(DISTINTA!$H$6:$H$85,"PILASTRO CUSCINETTO",DISTINTA!$S$6:$S$85) -> 271.19034 | E26: =SUMIF(DISTINTA!$H$6:$H$85,"PILASTRO CUSCINETTO",DISTINTA!$X$6:$X$85) -> 291.44922
A27: ASSI DI ROTAZIONE 1303 | C27: =SUMIF(DISTINTA!$H$6:$H$85,"ASSI DI ROTAZIONE 1303",DISTINTA!$Q$6:$Q$85) -> 155.595 | D27: =SUMIF(DISTINTA!$H$6:$H$85,"ASSI DI ROTAZIONE 1303",DISTINTA!$S$6:$S$85) -> 189.75 | E27: =SUMIF(DISTINTA!$H$6:$H$85,"ASSI DI ROTAZIONE 1303",DISTINTA!$X$6:$X$85) -> 235.29
A28: KIT OMEGA + PANNELLI | C28: =SUMIF(DISTINTA!$H$6:$H$85,"KIT OMEGA + PANNELLI",DISTINTA!$Q$6:$Q$85) -> 147.74866 | D28: =SUMIF(DISTINTA!$H$6:$H$85,"KIT OMEGA + PANNELLI",DISTINTA!$S$6:$S$85) -> 177.37567 | E28: =SUMIF(DISTINTA!$H$6:$H$85,"KIT OMEGA + PANNELLI",DISTINTA!$X$6:$X$85) -> 217.96279
A29: KIT INCLINOMETRO | C29: =SUMIF(DISTINTA!$H$6:$H$85,"KIT INCLINOMETRO",DISTINTA!$Q$6:$Q$85) -> 5.64077 | D29: =SUMIF(DISTINTA!$H$6:$H$85,"KIT INCLINOMETRO",DISTINTA!$S$6:$S$85) -> 176.39525 | E29: =SUMIF(DISTINTA!$H$6:$H$85,"KIT INCLINOMETRO",DISTINTA!$X$6:$X$85) -> 177.53249
A30: QUADRO AREA A | C30: =SUMIF(DISTINTA!$H$6:$H$85,"QUADRO AREA A",DISTINTA!$Q$6:$Q$85) -> 15 | D30: =SUMIF(DISTINTA!$H$6:$H$85,"QUADRO AREA A",DISTINTA!$S$6:$S$85) -> 1000 | E30: =SUMIF(DISTINTA!$H$6:$H$85,"QUADRO AREA A",DISTINTA!$X$6:$X$85) -> 1000
A31: QUADRO GENERALE | C31: =SUMIF(DISTINTA!$H$6:$H$85,"QUADRO GENERALE",DISTINTA!$Q$6:$Q$85) -> 20 | D31: =SUMIF(DISTINTA!$H$6:$H$85,"QUADRO GENERALE",DISTINTA!$S$6:$S$85) -> 1800 | E31: =SUMIF(DISTINTA!$H$6:$H$85,"QUADRO GENERALE",DISTINTA!$X$6:$X$85) -> 1800
A32: CENTRALINA METEO | C32: =SUMIF(DISTINTA!$H$6:$H$85,"CENTRALINA METEO",DISTINTA!$Q$6:$Q$85) -> 7 | D32: =SUMIF(DISTINTA!$H$6:$H$85,"CENTRALINA METEO",DISTINTA!$S$6:$S$85) -> 1900 | E32: =SUMIF(DISTINTA!$H$6:$H$85,"CENTRALINA METEO",DISTINTA!$X$6:$X$85) -> 1900
A34: Per categoria componente | C34: Peso (kg) | D34: Costo (€) | E34: Prezzo finale (€)
A35: STRUTTURA | C35: =SUMIF(DISTINTA!$L$6:$L$85,"STRUTTURA",DISTINTA!$Q$6:$Q$85) -> 529.83521 | D35: =SUMIF(DISTINTA!$L$6:$L$85,"STRUTTURA",DISTINTA!$S$6:$S$85) -> 674.53275 | E35: =SUMIF(DISTINTA!$L$6:$L$85,"STRUTTURA",DISTINTA!$X$6:$X$85) -> 788.79087
A36: PEZZI SPECIALI | C36: =SUMIF(DISTINTA!$L$6:$L$85,"PEZZI SPECIALI",DISTINTA!$Q$6:$Q$85) -> 16.01214 | D36: =SUMIF(DISTINTA!$L$6:$L$85,"PEZZI SPECIALI",DISTINTA!$S$6:$S$85) -> 22.84659 | E36: =SUMIF(DISTINTA!$L$6:$L$85,"PEZZI SPECIALI",DISTINTA!$X$6:$X$85) -> 27.53307
A37: BULLONERIA | C37: =SUMIF(DISTINTA!$L$6:$L$85,"BULLONERIA",DISTINTA!$Q$6:$Q$85) -> 16.3648 | D37: =SUMIF(DISTINTA!$L$6:$L$85,"BULLONERIA",DISTINTA!$S$6:$S$85) -> 47.0804 | E37: =SUMIF(DISTINTA!$L$6:$L$85,"BULLONERIA",DISTINTA!$X$6:$X$85) -> 47.0804
A38: ELETTROMECCANICA | C38: =SUMIF(DISTINTA!$L$6:$L$85,"ELETTROMECCANICA",DISTINTA!$Q$6:$Q$85) -> 105.3 | D38: =SUMIF(DISTINTA!$L$6:$L$85,"ELETTROMECCANICA",DISTINTA!$S$6:$S$85) -> 5385 | E38: =SUMIF(DISTINTA!$L$6:$L$85,"ELETTROMECCANICA",DISTINTA!$X$6:$X$85) -> 5385
A40: TOTALE TRACKER 12 MODULI | C40: =SUM(C35:C38) -> 667.51215 | D40: =SUM(D35:D38) -> 6129.4597 | E40: =SUM(E35:E38) -> 6248.4043
A41: verifica (somma blocchi): | C41: =SUM(C25:C32) -> 667.51215 | D41: =SUM(D25:D32) -> 6129.4597 | E41: =SUM(E25:E32) -> 6248.4043
A42: di cui BULLONERIA: | C42: =SUMIF(DISTINTA!$L$6:$L$85,"BULLONERIA",DISTINTA!$Q$6:$Q$85) -> 16.3648 | E42: =SUMIF(DISTINTA!$L$6:$L$85,"BULLONERIA",DISTINTA!$X$6:$X$85) -> 47.0804
A44: Note:
A45: - Quantita' riferite al tracker 12 moduli (distinta materiali rev.3 + DISTINTA COMPLETA, col. 'Q.ta 12 mod').
A46: - Il configuratore cambia profilo (IPE/IPEA), spessore asse (3,0/2,5), tipo omega (2,0/1,8), tipo impianto e lunghezze: peso e prezzo si ricalcolano, le quantita' restano quelle dei 12 moduli.
A47: - Prezzi bulloneria = 0 finche' non si compila la colonna Costo (EUR/pz) nel foglio DATI-BULLONERIA.
A48: - Motoriduttore, inclinometro, cuscinetto e quadro sotto motore: peso/prezzo dal foglio DATI-ELETTROMECCANICA (15T-INCLINOMETRO = 170 €/pz, 1,5 kg).
A49: - Quadro Area A, Quadro Generale, Box centralina meteo e i 4 sensori meteo: quantita' impostabili nel foglio INPUT (non piu' fisse a 1), applicate nei blocchi QUADRO GENERALE e CENTRALINA METEO della DISTINTA. Escluso in questa fase: moduli FV.
A51: 6 ▸ SEPARAZIONE COSTI: TRACKER vs IMPIANTO
C53: Peso (kg) | D53: Costo (€) | E53: Prezzo finale (€)
A54: COSTO DI 1 TRACKER (12 moduli: Pilastro motore, Pilastro cuscinetto, Assi, Kit omega+pannelli, Kit inclinometro) | C54: =SUM(C25:C29) -> 625.51215 | D54: =SUM(D25:D29) -> 1429.4597 | E54: =SUM(E25:E29) -> 1548.4043
A55: COSTO DI IMPIANTO (Quadro Area A + Quadro Generale + Centralina meteo; NON dipende dal numero di tracker) | C55: =SUM(C30:C32) -> 42 | D55: =SUM(D30:D32) -> 4700 | E55: =SUM(E30:E32) -> 4700
A57: N. tracker (12 moduli) nell’impianto | C57: =N_TRACKER_IMPIANTO -> 1
A58: COSTO TOTALE IMPIANTO (= N. tracker × costo 1 tracker + costo di impianto) | C58: =C57*C54+C55 -> 667.51215 | D58: =C57*D54+D55 -> 6129.4597 | E58: =C57*E54+E55 -> 6248.4043
A60: Nota: questa sezione riguarda solo la configurazione 12 moduli di questo file. Se l'impianto include anche tracker 18/20/22/36/40 moduli, il relativo costo va sommato a parte (schede non ancora riorganizzate).

Sheet PREZZO FINALE
A1: PREZZO FINALE – Voci di prezzo e incidenza dei costi
A2: Materiale + Zincatura + Lavorazione + Commerciale, per categoria e per blocco. Dati dal foglio DISTINTA.
A66: 4 · VOCI DEL PREZZO FINALE (materiale + zincatura + lavorazione + commerciale)
A67: Per categoria componente | C67: Materiale (€) | D67: Zincatura (€) | E67: Lavorazione (€) | F67: Commerciale (€) | G67: Prezzo finale (€) | H67: QUADRO AREA A | I67: 1
A68: STRUTTURA | C68: =SUMIF(DISTINTA!$L$6:$L$85,"STRUTTURA",DISTINTA!$T$6:$T$85) -> 542.05457 | D68: =SUMIF(DISTINTA!$L$6:$L$85,"STRUTTURA",DISTINTA!$U$6:$U$85) -> 132.47817 | E68: =SUMIF(DISTINTA!$L$6:$L$85,"STRUTTURA",DISTINTA!$V$6:$V$85) -> 114.25812 | F68: =SUMIF(DISTINTA!$L$6:$L$85,"STRUTTURA",DISTINTA!$W$6:$W$85) -> 0 | G68: =SUMIF(DISTINTA!$L$6:$L$85,"STRUTTURA",DISTINTA!$X$6:$X$85) -> 788.79087
A69: PEZZI SPECIALI | C69: =SUMIF(DISTINTA!$L$6:$L$85,"PEZZI SPECIALI",DISTINTA!$T$6:$T$85) -> 14.84052 | D69: =SUMIF(DISTINTA!$L$6:$L$85,"PEZZI SPECIALI",DISTINTA!$U$6:$U$85) -> 8.00607 | E69: =SUMIF(DISTINTA!$L$6:$L$85,"PEZZI SPECIALI",DISTINTA!$V$6:$V$85) -> 4.68648 | F69: =SUMIF(DISTINTA!$L$6:$L$85,"PEZZI SPECIALI",DISTINTA!$W$6:$W$85) -> 0 | G69: =SUMIF(DISTINTA!$L$6:$L$85,"PEZZI SPECIALI",DISTINTA!$X$6:$X$85) -> 27.53307
A70: BULLONERIA | C70: =SUMIF(DISTINTA!$L$6:$L$85,"BULLONERIA",DISTINTA!$T$6:$T$85) -> 0 | D70: =SUMIF(DISTINTA!$L$6:$L$85,"BULLONERIA",DISTINTA!$U$6:$U$85) -> 0 | E70: =SUMIF(DISTINTA!$L$6:$L$85,"BULLONERIA",DISTINTA!$V$6:$V$85) -> 0 | F70: =SUMIF(DISTINTA!$L$6:$L$85,"BULLONERIA",DISTINTA!$W$6:$W$85) -> 47.0804 | G70: =SUMIF(DISTINTA!$L$6:$L$85,"BULLONERIA",DISTINTA!$X$6:$X$85) -> 47.0804
A71: ELETTROMECCANICA | C71: =SUMIF(DISTINTA!$L$6:$L$85,"ELETTROMECCANICA",DISTINTA!$T$6:$T$85) -> 0 | D71: =SUMIF(DISTINTA!$L$6:$L$85,"ELETTROMECCANICA",DISTINTA!$U$6:$U$85) -> 0 | E71: =SUMIF(DISTINTA!$L$6:$L$85,"ELETTROMECCANICA",DISTINTA!$V$6:$V$85) -> 0 | F71: =SUMIF(DISTINTA!$L$6:$L$85,"ELETTROMECCANICA",DISTINTA!$W$6:$W$85) -> 5385 | G71: =SUMIF(DISTINTA!$L$6:$L$85,"ELETTROMECCANICA",DISTINTA!$X$6:$X$85) -> 5385
A72: TOTALE | C72: =SUM(C68:C71) -> 556.89509 | D72: =SUM(D68:D71) -> 140.48424 | E72: =SUM(E68:E71) -> 118.9446 | F72: =SUM(F68:F71) -> 5432.0804 | G72: =SUM(G68:G71) -> 6248.4043
A74: Per blocco di assieme | C74: Materiale (€) | D74: Zincatura (€) | E74: Lavorazione (€) | F74: Commerciale (€) | G74: Prezzo finale (€)
A75: PILASTRO MOTORE | C75: =SUMIF(DISTINTA!$H$6:$H$85,"PILASTRO MOTORE",DISTINTA!$T$6:$T$85) -> 78.81504 | D75: =SUMIF(DISTINTA!$H$6:$H$85,"PILASTRO MOTORE",DISTINTA!$U$6:$U$85) -> 42.51864 | E75: =SUMIF(DISTINTA!$H$6:$H$85,"PILASTRO MOTORE",DISTINTA!$V$6:$V$85) -> 11.42136 | F75: =SUMIF(DISTINTA!$H$6:$H$85,"PILASTRO MOTORE",DISTINTA!$W$6:$W$85) -> 493.4148 | G75: =SUMIF(DISTINTA!$H$6:$H$85,"PILASTRO MOTORE",DISTINTA!$X$6:$X$85) -> 626.16984
A76: PILASTRO CUSCINETTO | C76: =SUMIF(DISTINTA!$H$6:$H$85,"PILASTRO CUSCINETTO",DISTINTA!$T$6:$T$85) -> 150.75512 | D76: =SUMIF(DISTINTA!$H$6:$H$85,"PILASTRO CUSCINETTO",DISTINTA!$U$6:$U$85) -> 81.32842 | E76: =SUMIF(DISTINTA!$H$6:$H$85,"PILASTRO CUSCINETTO",DISTINTA!$V$6:$V$85) -> 20.25888 | F76: =SUMIF(DISTINTA!$H$6:$H$85,"PILASTRO CUSCINETTO",DISTINTA!$W$6:$W$85) -> 39.1068 | G76: =SUMIF(DISTINTA!$H$6:$H$85,"PILASTRO CUSCINETTO",DISTINTA!$X$6:$X$85) -> 291.44922
A77: ASSI DI ROTAZIONE 1303 | C77: =SUMIF(DISTINTA!$H$6:$H$85,"ASSI DI ROTAZIONE 1303",DISTINTA!$T$6:$T$85) -> 189.75 | D77: =SUMIF(DISTINTA!$H$6:$H$85,"ASSI DI ROTAZIONE 1303",DISTINTA!$U$6:$U$85) -> 0 | E77: =SUMIF(DISTINTA!$H$6:$H$85,"ASSI DI ROTAZIONE 1303",DISTINTA!$V$6:$V$85) -> 45.54 | F77: =SUMIF(DISTINTA!$H$6:$H$85,"ASSI DI ROTAZIONE 1303",DISTINTA!$W$6:$W$85) -> 0 | G77: =SUMIF(DISTINTA!$H$6:$H$85,"ASSI DI ROTAZIONE 1303",DISTINTA!$X$6:$X$85) -> 235.29
A78: KIT OMEGA + PANNELLI | C78: =SUMIF(DISTINTA!$H$6:$H$85,"KIT OMEGA + PANNELLI",DISTINTA!$T$6:$T$85) -> 133.97367 | D78: =SUMIF(DISTINTA!$H$6:$H$85,"KIT OMEGA + PANNELLI",DISTINTA!$U$6:$U$85) -> 14.6944 | E78: =SUMIF(DISTINTA!$H$6:$H$85,"KIT OMEGA + PANNELLI",DISTINTA!$V$6:$V$85) -> 40.58712 | F78: =SUMIF(DISTINTA!$H$6:$H$85,"KIT OMEGA + PANNELLI",DISTINTA!$W$6:$W$85) -> 28.7076 | G78: =SUMIF(DISTINTA!$H$6:$H$85,"KIT OMEGA + PANNELLI",DISTINTA!$X$6:$X$85) -> 217.96279
A79: KIT INCLINOMETRO | C79: =SUMIF(DISTINTA!$H$6:$H$85,"KIT INCLINOMETRO",DISTINTA!$T$6:$T$85) -> 3.60126 | D79: =SUMIF(DISTINTA!$H$6:$H$85,"KIT INCLINOMETRO",DISTINTA!$U$6:$U$85) -> 1.942785 | E79: =SUMIF(DISTINTA!$H$6:$H$85,"KIT INCLINOMETRO",DISTINTA!$V$6:$V$85) -> 1.13724 | F79: =SUMIF(DISTINTA!$H$6:$H$85,"KIT INCLINOMETRO",DISTINTA!$W$6:$W$85) -> 170.8512 | G79: =SUMIF(DISTINTA!$H$6:$H$85,"KIT INCLINOMETRO",DISTINTA!$X$6:$X$85) -> 177.53249
A80: QUADRO AREA A | C80: =SUMIF(DISTINTA!$H$6:$H$85,"QUADRO AREA A",DISTINTA!$T$6:$T$85) -> 0 | D80: =SUMIF(DISTINTA!$H$6:$H$85,"QUADRO AREA A",DISTINTA!$U$6:$U$85) -> 0 | E80: =SUMIF(DISTINTA!$H$6:$H$85,"QUADRO AREA A",DISTINTA!$V$6:$V$85) -> 0 | F80: =SUMIF(DISTINTA!$H$6:$H$85,"QUADRO AREA A",DISTINTA!$W$6:$W$85) -> 1000 | G80: =SUMIF(DISTINTA!$H$6:$H$85,"QUADRO AREA A",DISTINTA!$X$6:$X$85) -> 1000
A81: QUADRO GENERALE | C81: =SUMIF(DISTINTA!$H$6:$H$85,"QUADRO GENERALE",DISTINTA!$T$6:$T$85) -> 0 | D81: =SUMIF(DISTINTA!$H$6:$H$85,"QUADRO GENERALE",DISTINTA!$U$6:$U$85) -> 0 | E81: =SUMIF(DISTINTA!$H$6:$H$85,"QUADRO GENERALE",DISTINTA!$V$6:$V$85) -> 0 | F81: =SUMIF(DISTINTA!$H$6:$H$85,"QUADRO GENERALE",DISTINTA!$W$6:$W$85) -> 1800 | G81: =SUMIF(DISTINTA!$H$6:$H$85,"QUADRO GENERALE",DISTINTA!$X$6:$X$85) -> 1800
A82: CENTRALINA METEO | C82: =SUMIF(DISTINTA!$H$6:$H$85,"CENTRALINA METEO",DISTINTA!$T$6:$T$85) -> 0 | D82: =SUMIF(DISTINTA!$H$6:$H$85,"CENTRALINA METEO",DISTINTA!$U$6:$U$85) -> 0 | E82: =SUMIF(DISTINTA!$H$6:$H$85,"CENTRALINA METEO",DISTINTA!$V$6:$V$85) -> 0 | F82: =SUMIF(DISTINTA!$H$6:$H$85,"CENTRALINA METEO",DISTINTA!$W$6:$W$85) -> 1900 | G82: =SUMIF(DISTINTA!$H$6:$H$85,"CENTRALINA METEO",DISTINTA!$X$6:$X$85) -> 1900
A83: TOTALE | C83: =SUM(C75:C82) -> 556.89509 | D83: =SUM(D75:D82) -> 140.48424 | E83: =SUM(E75:E82) -> 118.9446 | F83: =SUM(F75:F82) -> 5432.0804 | G83: =SUM(G75:G82) -> 6248.4043
A85: verifica (per categoria ▸ per blocco, atteso 0) | C85: =G72-G83 -> 0
A87: Prezzo finale = Materiale + Zincatura + Lavorazione (0,30 EUR/kg sul peso netto) + Commerciale. Materiale + Zincatura = 'Costo (EUR)' del riepilogo sopra (STRUTTURA/PEZZI SPECIALI) e Commerciale = quello di BULLONERIA/ELETTROMECCANICA; la Lavorazione e' la voce aggiunta.
A89: 5 ▸ INCIDENZA DEI COSTI SUL PRODOTTO
A90: Per voce del prezzo finale | C90: Importo (€) | D90: Incidenza %
A91: Materiale | C91: =C72 -> 556.89509 | D91: =C91/$C$95 -> 0.089125969
A92: Zincatura | C92: =D72 -> 140.48424 | D92: =C92/$C$95 -> 0.022483219
A93: Lavorazione | C93: =E72 -> 118.9446 | D93: =C93/$C$95 -> 0.019035996
A94: Commerciale | C94: =F72 -> 5432.0804 | D94: =C94/$C$95 -> 0.86935482
A95: TOTALE | C95: =SUM(C91:C94) -> 6248.4043 | D95: =C95/$C$95 -> 1
A97: Per blocco di assieme | C97: Importo (€) | D97: Incidenza %
A98: PILASTRO MOTORE | C98: =G75 -> 626.16984 | D98: =C98/$C$106 -> 0.10021276
A99: PILASTRO CUSCINETTO | C99: =G76 -> 291.44922 | D99: =C99/$C$106 -> 0.046643784
A100: ASSI DI ROTAZIONE 1303 | C100: =G77 -> 235.29 | D100: =C100/$C$106 -> 0.037656014
A101: KIT OMEGA + PANNELLI | C101: =G78 -> 217.96279 | D101: =C101/$C$106 -> 0.034882953
A102: KIT INCLINOMETRO | C102: =G79 -> 177.53249 | D102: =C102/$C$106 -> 0.028412451
A103: QUADRO AREA A | C103: =G80 -> 1000 | D103: =C103/$C$106 -> 0.16004086
A104: QUADRO GENERALE | C104: =G81 -> 1800 | D104: =C104/$C$106 -> 0.28807355
A105: CENTRALINA METEO | C105: =G82 -> 1900 | D105: =C105/$C$106 -> 0.30407763
A106: TOTALE | C106: =SUM(C98:C105) -> 6248.4043 | D106: =C106/$C$106 -> 1
A108: Per categoria componente | C108: Importo (€) | D108: Incidenza %
A109: STRUTTURA | C109: =G68 -> 788.79087 | D109: =C109/$C$113 -> 0.12623877
...

Sheet DISTINTA PER KIT
A1: DISTINTA PER KIT – TRACKER 12 MODULI (1303)
A2: Vista collegata al foglio 'DISTINTA': stessa distinta, raggruppata per kit di assieme (Pilastro motore, Pilastro cuscinetto, Assi, Kit omega+pannelli, Kit inclinometro, Quadro area A, Quadro Generale, Centralina meteo). Si aggiorna con la configurazione, ma le righe vanno estese a mano se si aggiungono nuovi blocchi/voci alla DISTINTA.
A3: Blocco | B3: Pos. | C3: Codice | D3: Descrizione | E3: Categoria | F3: Profilo / tipo | G3: Lungh. (m) | H3: Q.tà tracker | I3: Peso unit. (kg) | J3: Peso tot. (kg) | K3: Prezzo unit. (€) | L3: Importo (€) | M3: Materiale (€) | N3: Zincatura (€) | O3: Lavorazione (€) | P3: Commerciale (€) | Q3: Prezzo finale (€)
A4: =DISTINTA!H6 -> PILASTRO MOTORE | B4: =DISTINTA!I6 -> 1 | C4: =DISTINTA!J6 -> TTS.PF.001.IPE140.30 | D4: =DISTINTA!K6 -> Pilastro fondazione trave IPE 140 mt.003 | E4: =DISTINTA!L6 -> STRUTTURA | F4: =DISTINTA!M6 -> IPE 140 | G4: =DISTINTA!N6 -> 3 | H4: =DISTINTA!O6 -> 1 | ... Q4: =DISTINTA!X6 -> 60.46875
A5: =DISTINTA!H7 -> PILASTRO MOTORE | B5: =DISTINTA!I7 -> 2 | C5: =DISTINTA!J7 -> TTS.PM.001.IPE140.22 | D5: =DISTINTA!K7 -> Pilastro motore trave IPE 140 mt.002 | E5: =DISTINTA!L7 -> STRUTTURA | F5: =DISTINTA!M7 -> IPE 140 | G5: =DISTINTA!N7 -> 2.22 | H5: =DISTINTA!O7 -> 1 | ... Q5: =DISTINTA!X7 -> 44.746875
A6: =DISTINTA!H8 -> PILASTRO MOTORE | B6: =DISTINTA!I8 -> 3 | C6: =DISTINTA!J8 -> TTS.PF.002.IPE140 | D6: =DISTINTA!K8 -> Piastra giunzione montanti centrali 200x100x4 (8 fori Ø11) | E6: =DISTINTA!L8 -> PEZZI SPECIALI | F6: =DISTINTA!M8 -> Lamiera 4mm | G6: =DISTINTA!N8 -> 0 | H6: =DISTINTA!O8 -> 2 | ... Q6: =DISTINTA!X8 -> 2.1996
A7: =DISTINTA!H9 -> PILASTRO MOTORE | B7: =DISTINTA!I9 -> 4 | C7: =DISTINTA!J9 -> TTS.PF.003.IPE140 | D7: =DISTINTA!K9 -> Piastra giunzione montanti esterna 240x70x6 (12 fori Ø11) | E7: =DISTINTA!L9 -> PEZZI SPECIALI | F7: =DISTINTA!M9 -> Lamiera 6mm | G7: =DISTINTA!N9 -> 0 | H7: =DISTINTA!O9 -> 2 | ... Q7: =DISTINTA!X9 -> 2.771355
A8: =DISTINTA!H10 -> PILASTRO MOTORE | B8: =DISTINTA!I10 -> 5 | C8: =DISTINTA!J10 -> TTS.PF.004.IPE140 | D8: =DISTINTA!K10 -> Piastra giunzione montanti interna 240x25x6 (6 fori Ø11) | E8: =DISTINTA!L10 -> PEZZI SPECIALI | F8: =DISTINTA!M10 -> Lamiera 6mm | G8: =DISTINTA!N10 -> 0 | H8: =DISTINTA!O10 -> 4 | ... Q8: =DISTINTA!X10 -> 1.97964
A9: =DISTINTA!H11 -> PILASTRO MOTORE | B9: =DISTINTA!I11 -> 6 | C9: =DISTINTA!J11 -> TTS.PM.002.IPE140 | D9: =DISTINTA!K11 -> Supporto laterale testa riduttore | E9: =DISTINTA!L11 -> STRUTTURA | F9: =DISTINTA!M11 -> Lamiera 8mm | G9: =DISTINTA!N11 -> 0 | H9: =DISTINTA!O11 -> 2 | ... Q9: =DISTINTA!X11 -> 16.11207
A10: =DISTINTA!H12 -> PILASTRO MOTORE | B10: =DISTINTA!I12 -> 7 | C10: =DISTINTA!J12 -> TTS.PM.003.IPE140 | D10: =DISTINTA!K12 -> Testa riduttore pilastro motore | E10: =DISTINTA!L12 -> STRUTTURA | F10: =DISTINTA!M12 -> Lamiera 4mm | G10: =DISTINTA!N12 -> 0 | H10: =DISTINTA!O12 -> 1 | ... Q10: =DISTINTA!X12 -> 4.47675
A11: =DISTINTA!H13 -> PILASTRO MOTORE | B11: =DISTINTA!I13 -> 8 | C11: =DISTINTA!J13 -> 10BZ10X40 | D11: =DISTINTA!K13 -> Bullone testa esagonale zn M10X40 | E11: =DISTINTA!L13 -> BULLONERIA | F11: =DISTINTA!M13 -> 0 | G11: =DISTINTA!N13 -> 0 | H11: =DISTINTA!O13 -> 32 | ... Q11: =DISTINTA!X13 -> 2.2656
A12: =DISTINTA!H14 -> PILASTRO MOTORE | B12: =DISTINTA!I14 -> 9 | C12: =DISTINTA!J14 -> 10BZM10X40 | D12: =DISTINTA!K14 -> Bullone testa esagonale M10X40 | E12: =DISTINTA!L14 -> BULLONERIA | F12: =DISTINTA!M14 -> 0 | G12: =DISTINTA!N14 -> 0 | H12: =DISTINTA!O14 -> 8 | ... Q12: =DISTINTA!X14 -> 0.5664
A13: =DISTINTA!H15 -> PILASTRO MOTORE | B13: =DISTINTA!I15 -> 10 | C13: =DISTINTA!J15 -> 10BZM16X60 | D13: =DISTINTA!K15 -> Bullone testa esagonale M16X60 | E13: =DISTINTA!L15 -> BULLONERIA | F13: =DISTINTA!M15 -> 0 | G13: =DISTINTA!N15 -> 0 | H13: =DISTINTA!O15 -> 4 | ... Q13: =DISTINTA!X15 -> 1.1868
A14: =DISTINTA!H16 -> PILASTRO MOTORE | B14: =DISTINTA!I16 -> 11 | C14: =DISTINTA!J16 -> 10ROND10 | D14: =DISTINTA!K16 -> Rondella zn da 10 | E14: =DISTINTA!L16 -> BULLONERIA | F14: =DISTINTA!M16 -> 0 | G14: =DISTINTA!N16 -> 0 | H14: =DISTINTA!O16 -> 80 | ... Q14: =DISTINTA!X16 -> 0.736
A15: =DISTINTA!H17 -> PILASTRO MOTORE | B15: =DISTINTA!I17 -> 12 | C15: =DISTINTA!J17 -> 10ROND16 | D15: =DISTINTA!K17 -> Rondella zn da 16 | E15: =DISTINTA!L17 -> BULLONERIA | F15: =DISTINTA!M17 -> 0 | G15: =DISTINTA!N17 -> 0 | H15: =DISTINTA!O17 -> 8 | ... Q15: =DISTINTA!X17 -> 0.2472
... A20: =DISTINTA!H22 -> PILASTRO MOTORE | B20: =DISTINTA!I22 -> 17 | C20: =DISTINTA!J22 -> 10S-FC | D20: =DISTINTA!K22 -> Finecorsa elettrico | E20: =DISTINTA!L22 -> ELETTROMECCANICA | F20: =DISTINTA!M22 -> 0 | G20: =DISTINTA!N22 -> 0 | H20: =DISTINTA!O22 -> 1 | ... Q20: =DISTINTA!X22 -> 27
D21: =DISTINTA!K23 -> ▸ PILASTRO MOTORE – TOTALE | J21: =DISTINTA!Q23 -> 143.42128 | L21: =DISTINTA!S23 -> 614.74848 | M21: =DISTINTA!T23 -> 78.81504 | N21: =DISTINTA!U23 -> 42.51864 | O21: =DISTINTA!V23 -> 11.42136 | P21: =DISTINTA!W23 -> 493.4148 | Q21: =DISTINTA!X23 -> 626.16984
A22: =DISTINTA!H24 -> PILASTRO CUSCINETTO | B22: =DISTINTA!I24 -> 1 | C22: =DISTINTA!J24 -> TTS.PF.001.IPE140.30 | D22: =DISTINTA!K24 -> Pilastro fondazione trave IPE 140 mt.003 | E22: =DISTINTA!L24 -> STRUTTURA | F22: =DISTINTA!M24 -> IPE 140 | G22: =DISTINTA!N24 -> 3 | H22: =DISTINTA!O24 -> 2 | ... Q22: =DISTINTA!X24 -> 120.9375
A23: =DISTINTA!H25 -> PILASTRO CUSCINETTO | B23: =DISTINTA!I25 -> 2 | C23: =DISTINTA!J25 -> TTS.PC.001.IPE140.23 | D23: =DISTINTA!K25 -> Pilastro cuscinetto trave IPE 140 mt.002 | E23: =DISTINTA!L25 -> STRUTTURA | F23: =DISTINTA!M25 -> IPE 140 | G23: =DISTINTA!N25 -> 2.3 | H23: =DISTINTA!O25 -> 2 | ... Q23: =DISTINTA!X25 -> 92.71875
A24: =DISTINTA!H26 -> PILASTRO CUSCINETTO | B24: =DISTINTA!I26 -> 3 | C24: =DISTINTA!J26 -> TTS.PF.002.IPE140 | D24: =DISTINTA!K26 -> Piastra giunzione montanti centrali 200x100x4 (8 fori Ø11) | E24: =DISTINTA!L26 -> PEZZI SPECIALI | F24: =DISTINTA!M26 -> Lamiera 4mm | G24: =DISTINTA!N26 -> 0 | H24: =DISTINTA!O26 -> 4 | ... Q24: =DISTINTA!X26 -> 4.3992
A25: =DISTINTA!H27 -> PILASTRO CUSCINETTO | B25: =DISTINTA!I27 -> 4 | C25: =DISTINTA!J27 -> TTS.PF.003.IPE140 | D25: =DISTINTA!K27 -> Piastra giunzione montanti esterna 240x70x6 (12 fori Ø11) | E25: =DISTINTA!L27 -> PEZZI SPECIALI | F25: =DISTINTA!M27 -> Lamiera 6mm | G25: =DISTINTA!N27 -> 0 | H25: =DISTINTA!O27 -> 4 | ... Q25: =DISTINTA!X27 -> 5.54271
A26: =DISTINTA!H28 -> PILASTRO CUSCINETTO | B26: =DISTINTA!I28 -> 5 | C26: =DISTINTA!J28 -> TTS.PF.004.IPE140 | D26: =DISTINTA!K28 -> Piastra giunzione montanti interna 240x25x6 (6 fori Ø11) | E26: =DISTINTA!L28 -> PEZZI SPECIALI | F26: =DISTINTA!M28 -> Lamiera 6mm | G26: =DISTINTA!N28 -> 0 | H26: =DISTINTA!O28 -> 8 | ... Q26: =DISTINTA!X28 -> 3.95928
A27: =DISTINTA!H29 -> PILASTRO CUSCINETTO | B27: =DISTINTA!I29 -> 6 | C27: =DISTINTA!J29 -> TTS.PC.002.IPE140 | D27: =DISTINTA!K29 -> Supporto laterale testa cuscinetto | E27: =DISTINTA!L29 -> STRUTTURA | F27: =DISTINTA!M29 -> Tubo quadro80x80x 6 | G27: =DISTINTA!N29 -> 0 | H27: =DISTINTA!O29 -> 4 | ... Q27: =DISTINTA!X29 -> 15.17724
A28: =DISTINTA!H30 -> PILASTRO CUSCINETTO | B28: =DISTINTA!I30 -> 7 | C28: =DISTINTA!J30 -> TTS.PC.003.IPE140 | D28: =DISTINTA!K30 -> Supporto testa cuscinetto | E28: =DISTINTA!L30 -> STRUTTURA | F28: =DISTINTA!M30 -> Lamiera 6mm | G28: =DISTINTA!N30 -> 0 | H28: =DISTINTA!O30 -> 2 | ... Q28: =DISTINTA!X30 -> 9.60774
A29: =DISTINTA!H31 -> PILASTRO CUSCINETTO | B29: =DISTINTA!I31 -> 8 | C29: =DISTINTA!J31 -> 10BZ10X30 | D29: =DISTINTA!K31 -> Bullone testa esagonale M10X30 | E29: =DISTINTA!L31 -> BULLONERIA | F29: =DISTINTA!M31 -> 0 | G29: =DISTINTA!N31 -> 0 | H29: =DISTINTA!O31 -> 8 | ... Q29: =DISTINTA!X31 -> 0.5072
A30: =DISTINTA!H32 -> PILASTRO CUSCINETTO | B30: =DISTINTA!I32 -> 9 | C30: =DISTINTA!J32 -> 10BZ16X140 | D30: =DISTINTA!K32 -> Bullone testa esagonale M16x140 mezzo filetto | E30: =DISTINTA!L32 -> BULLONERIA | F30: =DISTINTA!M32 -> 0 | G30: =DISTINTA!N32 -> 0 | H30: =DISTINTA!O32 -> 4 | ... Q30: =DISTINTA!X32 -> 2.2356
A31: =DISTINTA!H33 -> PILASTRO CUSCINETTO | B31: =DISTINTA!I33 -> 10 | C31: =DISTINTA!J33 -> 10BZM10X40 | D31: =DISTINTA!K33 -> Bullone testa esagonale M10X40 | E31: =DISTINTA!L33 -> BULLONERIA | F31: =DISTINTA!M33 -> 0 | G31: =DISTINTA!N33 -> 0 | H31: =DISTINTA!O33 -> 64 | ... Q31: =DISTINTA!X33 -> 4.5312
A32: =DISTINTA!H34 -> PILASTRO CUSCINETTO | B32: =DISTINTA!I34 -> 11 | C32: =DISTINTA!J34 -> 10ROND10 | D32: =DISTINTA!K34 -> Rondella zn da 10 | E32: =DISTINTA!L34 -> BULLONERIA | F32: =DISTINTA!M34 -> 0 | G32: =DISTINTA!N34 -> 0 | H32: =DISTINTA!O34 -> 144 | ... Q32: =DISTINTA!X34 -> 1.3248
A33: =DISTINTA!H35 -> PILASTRO CUSCINETTO | B33: =DISTINTA!I35 -> 12 | C33: =DISTINTA!J35 -> 10ROND16 | D33: =DISTINTA!K35 -> Rondella zn da 16 | E33: =DISTINTA!L35 -> BULLONERIA | F33: =DISTINTA!M35 -> 0 | G33: =DISTINTA!N35 -> 0 | H33: =DISTINTA!O35 -> 8 | ... Q33: =DISTINTA!X35 -> 0.2472
... A36: =DISTINTA!H38 -> PILASTRO CUSCINETTO | B36: =DISTINTA!I38 -> 15 | C36: =DISTINTA!J38 -> 15T-CUSCINETTO | D36: =DISTINTA!K38 -> Cuscinetto asse di rotazione | E36: =DISTINTA!L38 -> ELETTROMECCANICA | F36: =DISTINTA!M38 -> 0 | G36: =DISTINTA!N38 -> 0 | H36: =DISTINTA!O38 -> 2 | ... Q36: =DISTINTA!X38 -> 28
D37: =DISTINTA!K39 -> ▸ PILASTRO CUSCINETTO – TOTALE | J37: =DISTINTA!Q39 -> 173.10644 | L37: =DISTINTA!S39 -> 271.19034 | M37: =DISTINTA!T39 -> 150.75512 | N37: =DISTINTA!U39 -> 81.32842 | O37: =DISTINTA!V39 -> 20.25888 | P37: =DISTINTA!W39 -> 39.1068 | Q37: =DISTINTA!X39 -> 291.44922
A38: =DISTINTA!H40 -> ASSI DI ROTAZIONE 1303 | B38: =DISTINTA!I40 -> 1 | C38: =DISTINTA!J40 -> TTS.AR.001.8250.25 | D38: =DISTINTA!K40 -> Asse lato motore 120x120x2,5 mm lungh. mt.008 | E38: =DISTINTA!L40 -> STRUTTURA | F38: =DISTINTA!M40 -> ASSE 120x120x2,5 | G38: =DISTINTA!N40 -> 8.25 | H38: =DISTINTA!O40 -> 2 | ... Q38: =DISTINTA!X40 -> 235.29
D39: =DISTINTA!K41 -> ▸ ASSI DI ROTAZIONE 1303 – TOTALE | J39: =DISTINTA!Q41 -> 155.595 | L39: =DISTINTA!S41 -> 189.75 | M39: =DISTINTA!T41 -> 189.75 | N39: =DISTINTA!U41 -> 0 | O39: =DISTINTA!V41 -> 45.54 | P39: =DISTINTA!W41 -> 0 | Q39: =DISTINTA!X41 -> 235.29
A40: =DISTINTA!H42 -> KIT OMEGA + PANNELLI | B40: =DISTINTA!I42 -> 1 | C40: =DISTINTA!J42 -> TTS.AR.3014 | D40: =DISTINTA!K42 -> Omega supporto pannello | E40: =DISTINTA!L42 -> STRUTTURA | F40: =DISTINTA!M42 -> OMEGA 2,0 | G40: =DISTINTA!N42 -> 1.5 | H40: =DISTINTA!O42 -> 14 | ... Q40: =DISTINTA!X42 -> 102.375
A41: =DISTINTA!H43 -> KIT OMEGA + PANNELLI | B41: =DISTINTA!I43 -> 2 | C41: =DISTINTA!J43 -> TTS.AR.3011 | D41: =DISTINTA!K43 -> Supporto a L superiore omega | E41: =DISTINTA!L43 -> STRUTTURA | F41: =DISTINTA!M43 -> SUPPORTO L | G41: =DISTINTA!N43 -> 0.63 | H41: =DISTINTA!O43 -> 28 | ... Q41: =DISTINTA!X43 -> 35.505792
A42: =DISTINTA!H44 -> KIT OMEGA + PANNELLI | B42: =DISTINTA!I44 -> 3 | C42: =DISTINTA!J44 -> TTS.AR.3012 | D42: =DISTINTA!K44 -> Supporto a V inferiore omega | E42: =DISTINTA!L44 -> STRUTTURA | F42: =DISTINTA!M44 -> SUPPORTO V | G42: =DISTINTA!N44 -> 1 | H42: =DISTINTA!O44 -> 28 | ... Q42: =DISTINTA!X44 -> 16.072
A43: =DISTINTA!H45 -> KIT OMEGA + PANNELLI | B43: =DISTINTA!I45 -> 4 | C43: =DISTINTA!J45 -> TTS.AR.3013 | D43: =DISTINTA!K45 -> Gaffa sotto omega | E43: =DISTINTA!L45 -> STRUTTURA | F43: =DISTINTA!M45 -> GAFFA | G43: =DISTINTA!N45 -> 1 | H43: =DISTINTA!O45 -> 14 | ... Q43: =DISTINTA!X45 -> 35.3024
A44: =DISTINTA!H46 -> KIT OMEGA + PANNELLI | B44: =DISTINTA!I46 -> 5 | C44: =DISTINTA!J46 -> 10BZM6X150 | D44: =DISTINTA!K46 -> Bullone testa esagonale zn M6X150 | E44: =DISTINTA!L46 -> BULLONERIA | F44: =DISTINTA!M46 -> 0 | G44: =DISTINTA!N46 -> 0 | H44: =DISTINTA!O46 -> 28 | ... Q44: =DISTINTA!X46 -> 6.1992
A45: =DISTINTA!H47 -> KIT OMEGA + PANNELLI | B45: =DISTINTA!I47 -> 6 | C45: =DISTINTA!J47 -> 10BZM8X25 | D45: =DISTINTA!K47 -> Bullone testa esagonale zn M8X25 | E45: =DISTINTA!L47 -> BULLONERIA | F45: =DISTINTA!M47 -> 0 | G45: =DISTINTA!N47 -> 0 | H45: =DISTINTA!O47 -> 104 | ... Q45: =DISTINTA!X47 -> 3.0888
A46: =DISTINTA!H48 -> KIT OMEGA + PANNELLI | B46: =DISTINTA!I48 -> 7 | C46: =DISTINTA!J48 -> 10BZM10X160 | D46: =DISTINTA!K48 -> Bullone testa esagonale zn M10X160 | E46: =DISTINTA!L48 -> BULLONERIA | F46: =DISTINTA!M48 -> 0 | G46: =DISTINTA!N48 -> 0 | H46: =DISTINTA!O48 -> 56 | ... Q46: =DISTINTA!X48 -> 15.0416
...

Sheet DISTINTA PER FAMIGLIA
A1: DISTINTA PER FAMIGLIA – TRACKER 12 MODULI (1303)
A2: Vista collegata al foglio 'DISTINTA': stessa distinta, raggruppata per famiglia/categoria componente (Struttura, Pezzi speciali, Bulloneria, Elettromeccanica). Si aggiorna con la configurazione, ma le righe vanno estese a mano se si aggiungono nuovi blocchi/voci alla DISTINTA.
A3: Blocco | B3: Pos. | C3: Codice | D3: Descrizione | E3: Categoria | F3: Profilo / tipo | G3: Lungh. (m) | H3: Q.tà tracker | I3: Peso unit. (kg) | J3: Peso tot. (kg) | K3: Prezzo unit. (€) | L3: Importo (€) | M3: Materiale (€) | N3: Zincatura (€) | O3: Lavorazione (€) | P3: Commerciale (€) | Q3: Prezzo finale (€)
A4: =DISTINTA!H6 -> PILASTRO MOTORE | B4: =DISTINTA!I6 -> 1 | C4: =DISTINTA!J6 -> TTS.PF.001.IPE140.30 | D4: =DISTINTA!K6 -> Pilastro fondazione trave IPE 140 mt.003 | E4: =DISTINTA!L6 -> STRUTTURA | F4: =DISTINTA!M6 -> IPE 140 | G4: =DISTINTA!N6 -> 3 | H4: =DISTINTA!O6 -> 1 | ... Q4: =DISTINTA!X6 -> 60.46875
A5: =DISTINTA!H7 -> PILASTRO MOTORE | B5: =DISTINTA!I7 -> 2 | C5: =DISTINTA!J7 -> TTS.PM.001.IPE140.22 | D5: =DISTINTA!K7 -> Pilastro motore trave IPE 140 mt.002 | E5: =DISTINTA!L7 -> STRUTTURA | F5: =DISTINTA!M7 -> IPE 140 | G5: =DISTINTA!N7 -> 2.22 | H5: =DISTINTA!O7 -> 1 | ... Q5: =DISTINTA!X7 -> 44.746875
A6: =DISTINTA!H11 -> PILASTRO MOTORE | B6: =DISTINTA!I11 -> 6 | C6: =DISTINTA!J11 -> TTS.PM.002.IPE140 | D6: =DISTINTA!K11 -> Supporto laterale testa riduttore | E6: =DISTINTA!L11 -> STRUTTURA | F6: =DISTINTA!M11 -> Lamiera 8mm | G6: =DISTINTA!N11 -> 0 | H6: =DISTINTA!O11 -> 2 | ... Q6: =DISTINTA!X11 -> 16.11207
A7: =DISTINTA!H12 -> PILASTRO MOTORE | B7: =DISTINTA!I12 -> 7 | C7: =DISTINTA!J12 -> TTS.PM.003.IPE140 | D7: =DISTINTA!K12 -> Testa riduttore pilastro motore | E7: =DISTINTA!L12 -> STRUTTURA | F7: =DISTINTA!M12 -> Lamiera 4mm | G7: =DISTINTA!N12 -> 0 | H7: =DISTINTA!O12 -> 1 | ... Q7: =DISTINTA!X12 -> 4.47675
A8: =DISTINTA!H24 -> PILASTRO CUSCINETTO | B8: =DISTINTA!I24 -> 1 | C8: =DISTINTA!J24 -> TTS.PF.001.IPE140.30 | D8: =DISTINTA!K24 -> Pilastro fondazione trave IPE 140 mt.003 | E8: =DISTINTA!L24 -> STRUTTURA | F8: =DISTINTA!M24 -> IPE 140 | G8: =DISTINTA!N24 -> 3 | H8: =DISTINTA!O24 -> 2 | ... Q8: =DISTINTA!X24 -> 120.9375
A9: =DISTINTA!H25 -> PILASTRO CUSCINETTO | B9: =DISTINTA!I25 -> 2 | C9: =DISTINTA!J25 -> TTS.PC.001.IPE140.23 | D9: =DISTINTA!K25 -> Pilastro cuscinetto trave IPE 140 mt.002 | E9: =DISTINTA!L25 -> STRUTTURA | F9: =DISTINTA!M25 -> IPE 140 | G9: =DISTINTA!N25 -> 2.3 | H9: =DISTINTA!O25 -> 2 | ... Q9: =DISTINTA!X25 -> 92.71875
A10: =DISTINTA!H29 -> PILASTRO CUSCINETTO | B10: =DISTINTA!I29 -> 6 | C10: =DISTINTA!J29 -> TTS.PC.002.IPE140 | D10: =DISTINTA!K29 -> Supporto laterale testa cuscinetto | E10: =DISTINTA!L29 -> STRUTTURA | F10: =DISTINTA!M29 -> Tubo quadro80x80x 6 | G10: =DISTINTA!N29 -> 0 | H10: =DISTINTA!O29 -> 4 | ... Q10: =DISTINTA!X29 -> 15.17724
A11: =DISTINTA!H30 -> PILASTRO CUSCINETTO | B11: =DISTINTA!I30 -> 7 | C11: =DISTINTA!J30 -> TTS.PC.003.IPE140 | D11: =DISTINTA!K30 -> Supporto testa cuscinetto | E11: =DISTINTA!L30 -> STRUTTURA | F11: =DISTINTA!M30 -> Lamiera 6mm | G11: =DISTINTA!N30 -> 0 | H11: =DISTINTA!O30 -> 2 | ... Q11: =DISTINTA!X30 -> 9.60774
A12: =DISTINTA!H40 -> ASSI DI ROTAZIONE 1303 | B12: =DISTINTA!I40 -> 1 | C12: =DISTINTA!J40 -> TTS.AR.001.8250.25 | D12: =DISTINTA!K40 -> Asse lato motore 120x120x2,5 mm lungh. mt.008 | E12: =DISTINTA!L40 -> STRUTTURA | F12: =DISTINTA!M40 -> ASSE 120x120x2,5 | G12: =DISTINTA!N40 -> 8.25 | H12: =DISTINTA!O40 -> 2 | ... Q12: =DISTINTA!X40 -> 235.29
A13: =DISTINTA!H42 -> KIT OMEGA + PANNELLI | B13: =DISTINTA!I42 -> 1 | C13: =DISTINTA!J42 -> TTS.AR.3014 | D13: =DISTINTA!K42 -> Omega supporto pannello | E13: =DISTINTA!L42 -> STRUTTURA | F13: =DISTINTA!M42 -> OMEGA 2,0 | G13: =DISTINTA!N42 -> 1.5 | H13: =DISTINTA!O42 -> 14 | ... Q13: =DISTINTA!X42 -> 102.375
A14: =DISTINTA!H43 -> KIT OMEGA + PANNELLI | B14: =DISTINTA!I43 -> 2 | C14: =DISTINTA!J43 -> TTS.AR.3011 | D14: =DISTINTA!K43 -> Supporto a L superiore omega | E14: =DISTINTA!L43 -> STRUTTURA | F14: =DISTINTA!M43 -> SUPPORTO L | G14: =DISTINTA!N43 -> 0.63 | H14: =DISTINTA!O43 -> 28 | ... Q14: =DISTINTA!X43 -> 35.505792
A15: =DISTINTA!H44 -> KIT OMEGA + PANNELLI | B15: =DISTINTA!I44 -> 3 | C15: =DISTINTA!J44 -> TTS.AR.3012 | D15: =DISTINTA!K44 -> Supporto a V inferiore omega | E15: =DISTINTA!L44 -> STRUTTURA | F15: =DISTINTA!M44 -> SUPPORTO V | G15: =DISTINTA!N44 -> 1 | H15: =DISTINTA!O44 -> 28 | ... Q15: =DISTINTA!X44 -> 16.072
A16: =DISTINTA!H45 -> KIT OMEGA + PANNELLI | B16: =DISTINTA!I45 -> 4 | C16: =DISTINTA!J45 -> TTS.AR.3013 | D16: =DISTINTA!K45 -> Gaffa sotto omega | E16: =DISTINTA!L45 -> STRUTTURA | F16: =DISTINTA!M45 -> GAFFA | G16: =DISTINTA!N45 -> 1 | H16: =DISTINTA!O45 -> 14 | ... Q16: =DISTINTA!X45 -> 35.3024
D17: ▸ STRUTTURA – TOTALE | J17: =SUM(J4:J16) -> 529.83521 | L17: =SUM(L4:L16) -> 674.53275 | M17: =SUM(M4:M16) -> 542.05457 | N17: =SUM(N4:N16) -> 132.47817 | O17: =SUM(O4:O16) -> 114.25812 | P17: =SUM(P4:P16) -> 0 | Q17: =SUM(Q4:Q16) -> 788.79087
A18: =DISTINTA!H8 -> PILASTRO MOTORE | B18: =DISTINTA!I8 -> 3 | C18: =DISTINTA!J8 -> TTS.PF.002.IPE140 | D18: =DISTINTA!K8 -> Piastra giunzione montanti centrali 200x100x4 (8 fori Ø11) | E18: =DISTINTA!L8 -> PEZZI SPECIALI | F18: =DISTINTA!M8 -> Lamiera 4mm | G18: =DISTINTA!N8 -> 0 | H18: =DISTINTA!O8 -> 2 | ... Q18: =DISTINTA!X8 -> 2.1996
A19: =DISTINTA!H9 -> PILASTRO MOTORE | B19: =DISTINTA!I9 -> 4 | C19: =DISTINTA!J9 -> TTS.PF.003.IPE140 | D19: =DISTINTA!K9 -> Piastra giunzione montanti esterna 240x70x6 (12 fori Ø11) | E19: =DISTINTA!L9 -> PEZZI SPECIALI | F19: =DISTINTA!M9 -> Lamiera 6mm | G19: =DISTINTA!N9 -> 0 | H19: =DISTINTA!O9 -> 2 | ... Q19: =DISTINTA!X9 -> 2.771355
A20: =DISTINTA!H10 -> PILASTRO MOTORE | B20: =DISTINTA!I10 -> 5 | C20: =DISTINTA!J10 -> TTS.PF.004.IPE140 | D20: =DISTINTA!K10 -> Piastra giunzione montanti interna 240x25x6 (6 fori Ø11) | E20: =DISTINTA!L10 -> PEZZI SPECIALI | F20: =DISTINTA!M10 -> Lamiera 6mm | G20: =DISTINTA!N10 -> 0 | H20: =DISTINTA!O10 -> 4 | ... Q20: =DISTINTA!X10 -> 1.97964
A21: =DISTINTA!H26 -> PILASTRO CUSCINETTO | B21: =DISTINTA!I26 -> 3 | C21: =DISTINTA!J26 -> TTS.PF.002.IPE140 | D21: =DISTINTA!K26 -> Piastra giunzione montanti centrali 200x100x4 (8 fori Ø11) | E21: =DISTINTA!L26 -> PEZZI SPECIALI | F21: =DISTINTA!M26 -> Lamiera 4mm | G21: =DISTINTA!N26 -> 0 | H21: =DISTINTA!O26 -> 4 | ... Q21: =DISTINTA!X26 -> 4.3992
A22: =DISTINTA!H27 -> PILASTRO CUSCINETTO | B22: =DISTINTA!I27 -> 4 | C22: =DISTINTA!J27 -> TTS.PF.003.IPE140 | D22: =DISTINTA!K27 -> Piastra giunzione montanti esterna 240x70x6 (12 fori Ø11) | E22: =DISTINTA!L27 -> PEZZI SPECIALI | F22: =DISTINTA!M27 -> Lamiera 6mm | G22: =DISTINTA!N27 -> 0 | H22: =DISTINTA!O27 -> 4 | ... Q22: =DISTINTA!X27 -> 5.54271
A23: =DISTINTA!H28 -> PILASTRO CUSCINETTO | B23: =DISTINTA!I28 -> 5 | C23: =DISTINTA!J28 -> TTS.PF.004.IPE140 | D23: =DISTINTA!K28 -> Piastra giunzione montanti interna 240x25x6 (6 fori Ø11) | E23: =DISTINTA!L28 -> PEZZI SPECIALI | F23: =DISTINTA!M28 -> Lamiera 6mm | G23: =DISTINTA!N28 -> 0 | H23: =DISTINTA!O28 -> 8 | ... Q23: =DISTINTA!X28 -> 3.95928
A24: =DISTINTA!H56 -> KIT INCLINOMETRO | B24: =DISTINTA!I56 -> 1 | C24: =DISTINTA!J56 -> TTS.AR.4011 | D24: =DISTINTA!K56 -> Supporto superiore inclinometro | E24: =DISTINTA!L56 -> PEZZI SPECIALI | F24: =DISTINTA!M56 -> 0 | G24: =DISTINTA!N56 -> 0 | H24: =DISTINTA!O56 -> 1 | ... Q24: =DISTINTA!X56 -> 1.48473
A25: =DISTINTA!H57 -> KIT INCLINOMETRO | B25: =DISTINTA!I57 -> 2 | C25: =DISTINTA!J57 -> TTS.AR.4012 | D25: =DISTINTA!K57 -> Supporto inferiore inclinometro | E25: =DISTINTA!L57 -> PEZZI SPECIALI | F25: =DISTINTA!M57 -> 0 | G25: =DISTINTA!N57 -> 0 | H25: =DISTINTA!O57 -> 1 | ... Q25: =DISTINTA!X57 -> 5.196555
D26: ▸ PEZZI SPECIALI – TOTALE | J26: =SUM(J18:J25) -> 16.01214 | L26: =SUM(L18:L25) -> 22.84659 | M26: =SUM(M18:M25) -> 14.84052 | N26: =SUM(N18:N25) -> 8.00607 | O26: =SUM(O18:O25) -> 4.68648 | P26: =SUM(P18:P25) -> 0 | Q26: =SUM(Q18:Q25) -> 27.53307
A27: =DISTINTA!H13 -> PILASTRO MOTORE | B27: =DISTINTA!I13 -> 8 | C27: =DISTINTA!J13 -> 10BZ10X40 | D27: =DISTINTA!K13 -> Bullone testa esagonale zn M10X40 | E27: =DISTINTA!L13 -> BULLONERIA | F27: =DISTINTA!M13 -> 0 | G27: =DISTINTA!N13 -> 0 | H27: =DISTINTA!O13 -> 32 | ... Q27: =DISTINTA!X13 -> 2.2656
A28: =DISTINTA!H14 -> PILASTRO MOTORE | B28: =DISTINTA!I14 -> 9 | C28: =DISTINTA!J14 -> 10BZM10X40 | D28: =DISTINTA!K14 -> Bullone testa esagonale M10X40 | E28: =DISTINTA!L14 -> BULLONERIA | F28: =DISTINTA!M14 -> 0 | G28: =DISTINTA!N14 -> 0 | H28: =DISTINTA!O14 -> 8 | ... Q28: =DISTINTA!X14 -> 0.5664
A29: =DISTINTA!H15 -> PILASTRO MOTORE | B29: =DISTINTA!I15 -> 10 | C29: =DISTINTA!J15 -> 10BZM16X60 | D29: =DISTINTA!K15 -> Bullone testa esagonale M16X60 | E29: =DISTINTA!L15 -> BULLONERIA | F29: =DISTINTA!M15 -> 0 | G29: =DISTINTA!N15 -> 0 | H29: =DISTINTA!O15 -> 4 | ... Q29: =DISTINTA!X15 -> 1.1868
A30: =DISTINTA!H16 -> PILASTRO MOTORE | B30: =DISTINTA!I16 -> 11 | C30: =DISTINTA!J16 -> 10ROND10 | D30: =DISTINTA!K16 -> Rondella zn da 10 | E30: =DISTINTA!L16 -> BULLONERIA | F30: =DISTINTA!M16 -> 0 | G30: =DISTINTA!N16 -> 0 | H30: =DISTINTA!O16 -> 80 | ... Q30: =DISTINTA!X16 -> 0.736
A31: =DISTINTA!H17 -> PILASTRO MOTORE | B31: =DISTINTA!I17 -> 12 | C31: =DISTINTA!J17 -> 10ROND16 | D31: =DISTINTA!K17 -> Rondella zn da 16 | E31: =DISTINTA!L17 -> BULLONERIA | F31: =DISTINTA!M17 -> 0 | G31: =DISTINTA!N17 -> 0 | H31: =DISTINTA!O17 -> 8 | ... Q31: =DISTINTA!X17 -> 0.2472
A32: =DISTINTA!H18 -> PILASTRO MOTORE | B32: =DISTINTA!I18 -> 13 | C32: =DISTINTA!J18 -> 10DAZAM10 | D32: =DISTINTA!K18 -> Dado autobloccante M10 | E32: =DISTINTA!L18 -> BULLONERIA | F32: =DISTINTA!M18 -> 0 | G32: =DISTINTA!N18 -> 0 | H32: =DISTINTA!O18 -> 40 | ... Q32: =DISTINTA!X18 -> 1.06
A33: =DISTINTA!H19 -> PILASTRO MOTORE | B33: =DISTINTA!I19 -> 14 | C33: =DISTINTA!J19 -> 10DAZAM16 | D33: =DISTINTA!K19 -> Dado autobloccante M16 | E33: =DISTINTA!L19 -> BULLONERIA | F33: =DISTINTA!M19 -> 0 | G33: =DISTINTA!N19 -> 0 | H33: =DISTINTA!O19 -> 4 | ... Q33: =DISTINTA!X19 -> 0.3528
A34: =DISTINTA!H31 -> PILASTRO CUSCINETTO | B34: =DISTINTA!I31 -> 8 | C34: =DISTINTA!J31 -> 10BZ10X30 | D34: =DISTINTA!K31 -> Bullone testa esagonale M10X30 | E34: =DISTINTA!L31 -> BULLONERIA | F34: =DISTINTA!M31 -> 0 | G34: =DISTINTA!N31 -> 0 | H34: =DISTINTA!O31 -> 8 | ... Q34: =DISTINTA!X31 -> 0.5072
